#VRML_SIM R2023a utf8

EXTERNPROTO "https://raw.githubusercontent.com/cyberbotics/webots/R2023a/projects/objects/backgrounds/protos/TexturedBackground.proto"
EXTERNPROTO "https://raw.githubusercontent.com/cyberbotics/webots/R2023a/projects/objects/backgrounds/protos/TexturedBackgroundLight.proto"
EXTERNPROTO "https://raw.githubusercontent.com/cyberbotics/webots/R2023a/projects/objects/floors/protos/RectangleArena.proto"
EXTERNPROTO "https://raw.githubusercontent.com/cyberbotics/webots/R2023a/projects/objects/factory/containers/protos/WoodenBox.proto"
EXTERNPROTO "https://raw.githubusercontent.com/cyberbotics/webots/R2023a/projects/robots/boston_dynamics/spot/protos/Spot.proto"
IMPORTABLE EXTERNPROTO "https://raw.githubusercontent.com/cyberbotics/webots/R2023a/projects/objects/toys/protos/RubberDuck.proto"
IMPORTABLE EXTERNPROTO "https://raw.githubusercontent.com/cyberbotics/webots/R2023a/projects/objects/lego/protos/LegoWheel.proto"
IMPORTABLE EXTERNPROTO "https://raw.githubusercontent.com/cyberbotics/webots/R2023a/projects/objects/toys/protos/PaperBoat.proto"
IMPORTABLE EXTERNPROTO "https://raw.githubusercontent.com/cyberbotics/webots/R2023a/projects/objects/balls/protos/PingPongBall.proto"
IMPORTABLE EXTERNPROTO "https://raw.githubusercontent.com/cyberbotics/webots/R2023a/projects/objects/kitchen/utensils/protos/Fork.proto"
IMPORTABLE EXTERNPROTO "https://raw.githubusercontent.com/cyberbotics/webots/R2023a/projects/objects/balls/protos/SoccerBall.proto"
IMPORTABLE EXTERNPROTO "https://raw.githubusercontent.com/cyberbotics/webots/R2023a/projects/objects/bedroom/protos/PhotoFrame.proto"
IMPORTABLE EXTERNPROTO "https://raw.githubusercontent.com/cyberbotics/webots/R2023a/projects/robots/gctronic/e-puck/protos/E-puck.proto"
IMPORTABLE EXTERNPROTO "https://raw.githubusercontent.com/cyberbotics/webots/R2023a/projects/objects/drinks/protos/WaterBottle.proto"
IMPORTABLE EXTERNPROTO "https://raw.githubusercontent.com/cyberbotics/webots/R2023a/projects/objects/rocks/protos/Rock10cm.proto"
IMPORTABLE EXTERNPROTO "https://raw.githubusercontent.com/cyberbotics/webots/R2023a/projects/objects/plants/protos/FlowerPot.proto"
IMPORTABLE EXTERNPROTO "https://raw.githubusercontent.com/cyberbotics/webots/R2023a/projects/objects/computers/protos/ComputerMouse.proto"
EXTERNPROTO "https://raw.githubusercontent.com/cyberbotics/webots/R2023a/projects/objects/factory/conveyors/protos/ConveyorBelt.proto"

WorldInfo {
  basicTimeStep 8
}
Viewpoint {
  orientation 0.2913481687985301 0.2616871895849612 -0.9201282841782812 1.7602540895158325
  position 1.9385379870956154 4.7809595776542135 4.719275751657889
}
TexturedBackground {
}
TexturedBackgroundLight {
}
RectangleArena {
  translation 0.03 0 0
  floorSize 10 8
  wallThickness 0.1
  wallHeight 3
}
WoodenBox {
  translation 2.62 -0.46 1.63
  name "wooden box(3)"
  size 0.6 0.2 0.23
}
WoodenBox {
  translation 3.68407 1.0465 0.77
  rotation 0 0 1 0.785398
  name "wooden box(2)"
  size 1.5 0.9 1.5
}
WoodenBox {
  translation 2.22 0 0.77
  name "wooden box(4)"
  size 1.5 0.9 1.5
}
Robot {
  translation 2.84 -0.41 1.75
  rotation 0 0 1 1.5708
  scale 0.1 0.1 0.1
  children [
    SliderJoint {
      jointParameters JointParameters {
        axis 0.707 -0.707 0
      }
      device [
        LinearMotor {
          name "lr_l"
          acceleration 50
          consumptionFactor 1
          maxVelocity 100000
          maxPosition 8
          maxForce 100000
          multiplier 500
        }
      ]
      endPoint Solid {
        translation -0.095051469946176 3.4319233699461758 0.24
        rotation 0 0 1 -0.785395307179586
        children [
          Shape {
            appearance PBRAppearance {
            }
            geometry DEF LR Box {
              size 1.8 0.7 0.3
            }
          }
        ]
        name "solid(1)"
        boundingObject USE LR
        physics Physics {
          density -1
          mass 3
          centerOfMass [
            0 0 0
          ]
          inertiaMatrix [
            1.1700000000000006 29.520000000000014 29.970000000000013
            0 0 0
          ]
        }
      }
    }
    Solid {
      translation -0.330507 3.68106 0
      rotation 0 0 1 -0.785395307179586
      children [
        Shape {
          appearance PBRAppearance {
          }
          geometry Box {
            size 1.9 0.3 0.3
          }
        }
      ]
    }
    DistanceSensor {
      rotation 0 0.7071067811865475 0.7071067811865475 0
      children [
        Shape {
          appearance PBRAppearance {
          }
          geometry Capsule {
            height 0.1
            radius 0.05
          }
        }
      ]
      name "sens"
      lookupTable [
        0 0 0
        10 1 0
      ]
      aperture 0.05
    }
  ]
  name "dist"
  controller "belt_controller"
  supervisor TRUE
}
WoodenBox {
  translation 0 0 0.77
  name "wooden box(1)"
  size 2.6 1.1 1.5
}
WoodenBox {
  size 0.6 0.6 1.5
}
Spot {
  translation 3.59656 0.907573 2.12868
  rotation 0.0013580800558901547 0.003474660142995468 0.9999930411535134 0.785402
  controller "get_img"
}
WaterBottle {
  mass 8
}
ComputerMouse {
  translation -1.63861 0.00366 1.76
  name "computer mouse(2)"
  topColor 0.3 0.71 0.71
  bottomColor 0.7 0.7 0.056
}
RubberDuck {
  translation 0.19 0.01 1.78
}
PaperBoat {
  translation -0.95908 0.06689 1.76
  name "paper boat(1)"
}
PaperBoat {
  translation 0.95092 0.06689 1.76
  name "paper boat(2)"
}
PaperBoat {
  translation 2.39092 0.06689 1.76
  name "paper boat(3)"
}
FlowerPot {
  translation -1.39074 -0.0048813 1.8
  rotation 0 1 0 -1.5707953071795862
  physics Physics {
  }
}
E-puck {
  translation -0.310365 0.01909 1.74
  name "e-puck(1)"
  controller "<generic>"
}
E-puck {
  translation 1.71964 0.01909 1.76
  name "e-puck(2)"
  controller "<generic>"
}
Rock10cm {
  translation -1.70692 0.0441402 1.82
  rotation 0 1 0 -2.88
  name "rock 10 cm(3)"
  color 0 1 1
  physics Physics {
  }
}
ConveyorBelt {
  translation 0.87 0 1.53
  size 4.2 0.7 0.2
  borderThickness 1e-16
  borderHeight -0.1
  speed 0.4
}
